Workbook

Sheet 都道府県_確率計算
A1: 出生地ガチャ｜都道府県別 確率計算表
A2: 2025年確定数 · 国内47都道府県 · Excel側で計算してJSには完成値だけ渡す
A4: 基準年 | B4: 2025
A5: 元データ | B5: 現在のゲーム内47都道府県出生数
A6: 対象 | B6: 日本国内47都道府県・日本人出生
A8: 番号 | B8: 都道府県 | C8: 出生数（人） | D8: 抽選確率 | E8: 累積確率 | F8: JS貼付用 | G8: 出典ID
A9: 1 | B9: 北海道 | C9: 21802 | D9: =C9/$C$57 -> 0.03247946 | E9: =SUM($D$9:D9) -> 0.03247946 | F9: =="['"&B9&"',"&TEXT(E9,"0.000000000000")&"]," -> ['北海道',0.032479460116], | G9: 厚労省2025確定数・第4表／照合済み
A10: 2 | B10: 青森県 | C10: 4737 | D10: =C10/$C$57 -> 0.0070569307 | E10: =SUM($D$9:D10) -> 0.039536391 | F10: =="['"&B10&"',"&TEXT(E10,"0.000000000000")&"]," -> ['青森県',0.039536390790], | G10: 厚労省2025確定数・第4表／照合済み
A11: 3 | B11: 岩手県 | C11: 4823 | D11: =C11/$C$57 -> 0.0071850489 | E11: =SUM($D$9:D11) -> 0.04672144 | F11: =="['"&B11&"',"&TEXT(E11,"0.000000000000")&"]," -> ['岩手県',0.046721439691], | G11: 厚労省2025確定数・第4表／照合済み
A12: 4 | B12: 宮城県 | C12: 11079 | D12: =C12/$C$57 -> 0.016504905 | E12: =SUM($D$9:D12) -> 0.063226345 | F12: =="['"&B12&"',"&TEXT(E12,"0.000000000000")&"]," -> ['宮城県',0.063226344683], | G12: 厚労省2025確定数・第4表／照合済み
A13: 5 | B13: 秋田県 | C13: 3148 | D13: =C13/$C$57 -> 0.004689723 | E13: =SUM($D$9:D13) -> 0.067916068 | F13: =="['"&B13&"',"&TEXT(E13,"0.000000000000")&"]," -> ['秋田県',0.067916067664], | G13: 厚労省2025確定数・第4表／照合済み
A14: 6 | B14: 山形県 | C14: 4380 | D14: =C14/$C$57 -> 0.0065250911 | E14: =SUM($D$9:D14) -> 0.074441159 | F14: =="['"&B14&"',"&TEXT(E14,"0.000000000000")&"]," -> ['山形県',0.074441158725], | G14: 厚労省2025確定数・第4表／照合済み
A15: 7 | B15: 福島県 | C15: 7842 | D15: =C15/$C$57 -> 0.011682595 | E15: =SUM($D$9:D15) -> 0.086123753 | F15: =="['"&B15&"',"&TEXT(E15,"0.000000000000")&"]," -> ['福島県',0.086123753268], | G15: 厚労省2025確定数・第4表／照合済み
A16: 8 | B16: 茨城県 | C16: 13409 | D16: =C16/$C$57 -> 0.019976015 | E16: =SUM($D$9:D16) -> 0.10609977 | F16: =="['"&B16&"',"&TEXT(E16,"0.000000000000")&"]," -> ['茨城県',0.106099768344], | G16: 厚労省2025確定数・第4表／照合済み
A17: 9 | B17: 栃木県 | C17: 8932 | D17: =C17/$C$57 -> 0.013306419 | E17: =SUM($D$9:D17) -> 0.11940619 | F17: =="['"&B17&"',"&TEXT(E17,"0.000000000000")&"]," -> ['栃木県',0.119406186919], | G17: 厚労省2025確定数・第4表／照合済み
A18: 10 | B18: 群馬県 | C18: 8950 | D18: =C18/$C$57 -> 0.013333234 | E18: =SUM($D$9:D18) -> 0.13273942 | F18: =="['"&B18&"',"&TEXT(E18,"0.000000000000")&"]," -> ['群馬県',0.132739420935], | G18: 厚労省2025確定数・第4表／照合済み
A19: 11 | B19: 埼玉県 | C19: 38812 | D19: =C19/$C$57 -> 0.057820053 | E19: =SUM($D$9:D19) -> 0.19055947 | F19: =="['"&B19&"',"&TEXT(E19,"0.000000000000")&"]," -> ['埼玉県',0.190559474417], | G19: 厚労省2025確定数・第4表／照合済み
A20: 12 | B20: 千葉県 | C20: 32988 | D20: =C20/$C$57 -> 0.049143768 | E20: =SUM($D$9:D20) -> 0.23970324 | F20: =="['"&B20&"',"&TEXT(E20,"0.000000000000")&"]," -> ['千葉県',0.239703242434], | G20: 厚労省2025確定数・第4表／照合済み
... A55: 47 | B55: 沖縄県 | C55: 11511 | D55: =C55/$C$57 -> 0.017148476 | E55: =SUM($D$9:D55) -> 1 | F55: =="['"&B55&"',"&TEXT(E55,"0.000000000000")&"]," -> ['沖縄県',1.000000000000], | G55: 厚労省2025確定数・第4表／照合済み
B57: 国内47都道府県 合計 | C57: =SUM(C9:C55) -> 671255 | D57: =SUM(D9:D55) -> 1 | E57: =E55 -> 1
B58: 2025年全国確定出生数 | C58: 671270
B59: 住所地が外国の分 | C59: =C58-C57 -> 15
A62: F列の完成済み累積値をJavaScriptに貼り付ける。ブラウザ側で出生数合計・確率を再計算しない。
A63: 2026-10-28検証：厚労省2025年人口動態統計（確定数）第4表と47都道府県すべて一致（差異0）。
A64: 注意：人口動態統計は国内の日本人出生。外国籍住民を含む抽選には別の統計が必要。

Sheet 説明と出典
A1: 計算方法・出典
A3: 番号 | B3: 項目 | C3: 説明
A4: 1 | B4: C列の出生数 | C4: 既存試作の47都道府県別2025年出生数を移行
A5: 2 | B5: D列：抽選確率 | C5: C列を国内47県の合計 C57 で割る
A6: 3 | B6: E列：累積確率 | C6: D列を上から累積。最後の行は100%
A7: 4 | B7: F列：JS貼付用 | C7: 計算済みの累積値を文字列で出力。JS側では集計しない
A8: 5 | B8: 更新時 | C8: 出生数を差し替えたらD〜F列が再計算。完成値をゲームへ反映
A9: 6 | B9: 全国との15人の差 | C9: 外国の住所地を持つ出生15人は都道府県別に分配しない
A10: 7 | B10: 統計対象 | C10: 人口動態統計は国内の日本人出生。外国籍住民は含まない
A11: 8 | B11: 都道府県別原表 | C11: 2026年9月30日公開 e-Stat 上巻4-3。47都道府県すべて原表と照合済み（2026-10-28）
A14: 出典 | B14: URL
A15: e-Stat 確定数 上巻4-3 | B15: https://www.e-stat.go.jp/stat-search/files?cycle=7&layout=datalist&month=0&page=1&tclass1=000001053058&tclass2=000001053061&tclass3=000001053064&toukei=00450011&tstat=000001028897&year=20250
A16: 2025年の国内47県と全国の差 | B16: https://totonoe.tech/blog/jinko-doutai-2025-shizen-gen/

Sheet 市区町村_準備
A1: 市区町村別確率計算（今後実装）
A3: 公式データ未取得のため数値は未入力。架空の出生数は使わない。
A5: 都道府県コード | B5: 都道府県 | C5: 市区町村コード | D5: 市区町村 | E5: 出生者数 | F5: 累積確率（予定）

Sheet 原表照合_2025
A1: 2025年 人口動態統計（確定数）｜都道府県別出生数・原表照合
A2: 照合日：2026年10月28日。厚生労働省の公表資料・第4表を使用。
A4: 参考資料 | B4: https://www.mhlw.go.jp/toukei/saikin/hw/jinkou/kakutei25/dl/03_toukeihyoR07.pdf
A5: 対象 | B5: 日本国内の日本人出生数（47都道府県）。外国籍を含む全出生ではない。
A7: 番号 | B7: 都道府県 | C7: 公式原表 | D7: 計算表 | E7: 差異 | F7: 一致判定
A8: 1 | B8: 北海道 | C8: 21802 | D8: ='都道府県_確率計算'!C9 -> 21802 | E8: =D8-C8 -> 0 | F8: =IF(E8=0,"一致","不一致") -> 一致
A9: 2 | B9: 青森県 | C9: 4737 | D9: ='都道府県_確率計算'!C10 -> 4737 | E9: =D9-C9 -> 0 | F9: =IF(E9=0,"一致","不一致") -> 一致
A10: 3 | B10: 岩手県 | C10: 4823 | D10: ='都道府県_確率計算'!C11 -> 4823 | E10: =D10-C10 -> 0 | F10: =IF(E10=0,"一致","不一致") -> 一致
A11: 4 | B11: 宮城県 | C11: 11079 | D11: ='都道府県_確率計算'!C12 -> 11079 | E11: =D11-C11 -> 0 | F11: =IF(E11=0,"一致","不一致") -> 一致
A12: 5 | B12: 秋田県 | C12: 3148 | D12: ='都道府県_確率計算'!C13 -> 3148 | E12: =D12-C12 -> 0 | F12: =IF(E12=0,"一致","不一致") -> 一致
A13: 6 | B13: 山形県 | C13: 4380 | D13: ='都道府県_確率計算'!C14 -> 4380 | E13: =D13-C13 -> 0 | F13: =IF(E13=0,"一致","不一致") -> 一致
A14: 7 | B14: 福島県 | C14: 7842 | D14: ='都道府県_確率計算'!C15 -> 7842 | E14: =D14-C14 -> 0 | F14: =IF(E14=0,"一致","不一致") -> 一致
A15: 8 | B15: 茨城県 | C15: 13409 | D15: ='都道府県_確率計算'!C16 -> 13409 | E15: =D15-C15 -> 0 | F15: =IF(E15=0,"一致","不一致") -> 一致
A16: 9 | B16: 栃木県 | C16: 8932 | D16: ='都道府県_確率計算'!C17 -> 8932 | E16: =D16-C16 -> 0 | F16: =IF(E16=0,"一致","不一致") -> 一致
A17: 10 | B17: 群馬県 | C17: 8950 | D17: ='都道府県_確率計算'!C18 -> 8950 | E17: =D17-C17 -> 0 | F17: =IF(E17=0,"一致","不一致") -> 一致
A18: 11 | B18: 埼玉県 | C18: 38812 | D18: ='都道府県_確率計算'!C19 -> 38812 | E18: =D18-C18 -> 0 | F18: =IF(E18=0,"一致","不一致") -> 一致
A19: 12 | B19: 千葉県 | C19: 32988 | D19: ='都道府県_確率計算'!C20 -> 32988 | E19: =D19-C19 -> 0 | F19: =IF(E19=0,"一致","不一致") -> 一致
... A54: 47 | B54: 沖縄県 | C54: 11511 | D54: ='都道府県_確率計算'!C55 -> 11511 | E54: =D54-C54 -> 0 | F54: =IF(E54=0,"一致","不一致") -> 一致
B56: 国内47都道府県合計 | C56: =SUM(C8:C54) -> 671255 | D56: =SUM(D8:D54) -> 671255 | E56: =D56-C56 -> 0 | F56: =IF(E56=0,"一致","不一致") -> 一致
B57: 全国出生数（外国住所地含む） | C57: 671270
B58: 外国住所地の出生数 | C58: =C57-C56 -> 15
B60: 照合件数 | C60: 47 | D60: 不一致の件数 | E60: =COUNTIF(F8:F54,"不一致") -> 0
A62: 本シートの「公式原表」は公表数値を固定値で転記。D列以降は計算式で照合。

Sheet 抽選用_確率順
A1: 出生地ガチャ｜抽選用データ（出生数の多い順）
A2: 原本は「都道府県_確率計算」に保持。こちらは抽選高速化用の別シート。
A4: 並び順 | B4: 出生数の多い順（降順）
A5: 基準 | B5: 2025年人口動態統計（確定数）第4表
A6: 更新時の注意 | B6: 元表の出生数を変えた場合、抽選順は再並べ替えが必要
A8: 順位 | B8: 都道府県 | C8: 出生数（人） | D8: 抽選確率 | E8: 累積確率 | F8: JS用（確率・累積） | G8: 元データの行 | H8: 照合状態
A9: 1 | B9: ='都道府県_確率計算'!B21 -> 東京都 | C9: ='都道府県_確率計算'!C21 -> 85090 | D9: =C9/'都道府県_確率計算'!$C$57 -> 0.12676256 | E9: =SUM($D$9:D9) -> 0.12676256 | F9: ="["&CHAR(34)&B9&CHAR(34)&", "&TEXT(D9,"0.000000000000")&", "&TEXT(E9,"0.000000000000")&"]," -> ["東京都", 0.126762556703, 0.126762556703], | G9: 21 | H9: 公式原表照合済み
A10: 2 | B10: ='都道府県_確率計算'!B35 -> 大阪府 | C10: ='都道府県_確率計算'!C35 -> 52598 | D10: =C10/'都道府県_確率計算'!$C$57 -> 0.078357703 | E10: =SUM($D$9:D10) -> 0.20512026 | F10: ="["&CHAR(34)&B10&CHAR(34)&", "&TEXT(D10,"0.000000000000")&", "&TEXT(E10,"0.000000000000")&"]," -> ["大阪府", 0.078357703108, 0.205120259812], | G10: 35 | H10: 公式原表照合済み
A11: 3 | B11: ='都道府県_確率計算'!B22 -> 神奈川県 | C11: ='都道府県_確率計算'!C22 -> 50209 | D11: =C11/'都道府県_確率計算'!$C$57 -> 0.074798698 | E11: =SUM($D$9:D11) -> 0.27991896 | F11: ="["&CHAR(34)&B11&CHAR(34)&", "&TEXT(D11,"0.000000000000")&", "&TEXT(E11,"0.000000000000")&"]," -> ["神奈川県", 0.074798697961, 0.279918957773], | G11: 22 | H11: 公式原表照合済み
A12: 4 | B12: ='都道府県_確率計算'!B31 -> 愛知県 | C12: ='都道府県_確率計算'!C31 -> 44290 | D12: =C12/'都道府県_確率計算'!$C$57 -> 0.065980887 | E12: =SUM($D$9:D12) -> 0.34589984 | F12: ="["&CHAR(34)&B12&CHAR(34)&", "&TEXT(D12,"0.000000000000")&", "&TEXT(E12,"0.000000000000")&"]," -> ["愛知県", 0.065980886548, 0.345899844321], | G12: 31 | H12: 公式原表照合済み
A13: 5 | B13: ='都道府県_確率計算'!B19 -> 埼玉県 | C13: ='都道府県_確率計算'!C19 -> 38812 | D13: =C13/'都道府県_確率計算'!$C$57 -> 0.057820053 | E13: =SUM($D$9:D13) -> 0.4037199 | F13: ="["&CHAR(34)&B13&CHAR(34)&", "&TEXT(D13,"0.000000000000")&", "&TEXT(E13,"0.000000000000")&"]," -> ["埼玉県", 0.057820053482, 0.403719897803], | G13: 19 | H13: 公式原表照合済み
A14: 6 | B14: ='都道府県_確率計算'!B20 -> 千葉県 | C14: ='都道府県_確率計算'!C20 -> 32988 | D14: =C14/'都道府県_確率計算'!$C$57 -> 0.049143768 | E14: =SUM($D$9:D14) -> 0.45286367 | F14: ="["&CHAR(34)&B14&CHAR(34)&", "&TEXT(D14,"0.000000000000")&", "&TEXT(E14,"0.000000000000")&"]," -> ["千葉県", 0.049143768017, 0.452863665820], | G14: 20 | H14: 公式原表照合済み
A15: 7 | B15: ='都道府県_確率計算'!B48 -> 福岡県 | C15: ='都道府県_確率計算'!C48 -> 31710 | D15: =C15/'都道府県_確率計算'!$C$57 -> 0.047239872 | E15: =SUM($D$9:D15) -> 0.50010354 | F15: ="["&CHAR(34)&B15&CHAR(34)&", "&TEXT(D15,"0.000000000000")&", "&TEXT(E15,"0.000000000000")&"]," -> ["福岡県", 0.047239871584, 0.500103537404], | G15: 48 | H15: 公式原表照合済み
A16: 8 | B16: ='都道府県_確率計算'!B36 -> 兵庫県 | C16: ='都道府県_確率計算'!C36 -> 30110 | D16: =C16/'都道府県_確率計算'!$C$57 -> 0.044856277 | E16: =SUM($D$9:D16) -> 0.54495981 | F16: ="["&CHAR(34)&B16&CHAR(34)&", "&TEXT(D16,"0.000000000000")&", "&TEXT(E16,"0.000000000000")&"]," -> ["兵庫県", 0.044856276676, 0.544959814080], | G16: 36 | H16: 公式原表照合済み
A17: 9 | B17: ='都道府県_確率計算'!B9 -> 北海道 | C17: ='都道府県_確率計算'!C9 -> 21802 | D17: =C17/'都道府県_確率計算'!$C$57 -> 0.03247946 | E17: =SUM($D$9:D17) -> 0.57743927 | F17: ="["&CHAR(34)&B17&CHAR(34)&", "&TEXT(D17,"0.000000000000")&", "&TEXT(E17,"0.000000000000")&"]," -> ["北海道", 0.032479460116, 0.577439274195], | G17: 9 | H17: 公式原表照合済み
A18: 10 | B18: ='都道府県_確率計算'!B30 -> 静岡県 | C18: ='都道府県_確率計算'!C30 -> 17092 | D18: =C18/'都道府県_確率計算'!$C$57 -> 0.025462753 | E18: =SUM($D$9:D18) -> 0.60290203 | F18: ="["&CHAR(34)&B18&CHAR(34)&", "&TEXT(D18,"0.000000000000")&", "&TEXT(E18,"0.000000000000")&"]," -> ["静岡県", 0.025462752605, 0.602902026801], | G18: 30 | H18: 公式原表照合済み
A19: 11 | B19: ='都道府県_確率計算'!B42 -> 広島県 | C19: ='都道府県_確率計算'!C42 -> 15238 | D19: =C19/'都道府県_確率計算'!$C$57 -> 0.022700762 | E19: =SUM($D$9:D19) -> 0.62560279 | F19: ="["&CHAR(34)&B19&CHAR(34)&", "&TEXT(D19,"0.000000000000")&", "&TEXT(E19,"0.000000000000")&"]," -> ["広島県", 0.022700762005, 0.625602788806], | G19: 42 | H19: 公式原表照合済み
A20: 12 | B20: ='都道府県_確率計算'!B16 -> 茨城県 | C20: ='都道府県_確率計算'!C16 -> 13409 | D20: =C20/'都道府県_確率計算'!$C$57 -> 0.019976015 | E20: =SUM($D$9:D20) -> 0.6455788 | F20: ="["&CHAR(34)&B20&CHAR(34)&", "&TEXT(D20,"0.000000000000")&", "&TEXT(E20,"0.000000000000")&"]," -> ["茨城県", 0.019976015076, 0.645578803882], | G20: 16 | H20: 公式原表照合済み
A21: 13 | B21: ='都道府県_確率計算'!B34 -> 京都府 | C21: ='都道府県_確率計算'!C34 -> 12677 | D21: =C21/'都道府県_確率計算'!$C$57 -> 0.01888552 | E21: =SUM($D$9:D21) -> 0.66446432 | F21: ="["&CHAR(34)&B21&CHAR(34)&", "&TEXT(D21,"0.000000000000")&", "&TEXT(E21,"0.000000000000")&"]," -> ["京都府", 0.018885520406, 0.664464324288], | G21: 34 | H21: 公式原表照合済み
A22: 14 | B22: ='都道府県_確率計算'!B55 -> 沖縄県 | C22: ='都道府県_確率計算'!C55 -> 11511 | D22: =C22/'都道府県_確率計算'!$C$57 -> 0.017148476 | E22: =SUM($D$9:D22) -> 0.6816128 | F22: ="["&CHAR(34)&B22&CHAR(34)&", "&TEXT(D22,"0.000000000000")&", "&TEXT(E22,"0.000000000000")&"]," -> ["沖縄県", 0.017148475617, 0.681612799905], | G22: 55 | H22: 公式原表照合済み
A23: 15 | B23: ='都道府県_確率計算'!B12 -> 宮城県 | C23: ='都道府県_確率計算'!C12 -> 11079 | D23: =C23/'都道府県_確率計算'!$C$57 -> 0.016504905 | E23: =SUM($D$9:D23) -> 0.6981177 | F23: ="["&CHAR(34)&B23&CHAR(34)&", "&TEXT(D23,"0.000000000000")&", "&TEXT(E23,"0.000000000000")&"]," -> ["宮城県", 0.016504904991, 0.698117704896], | G23: 12 | H23: 公式原表照合済み
A24: 16 | B24: ='都道府県_確率計算'!B41 -> 岡山県 | C24: ='都道府県_確率計算'!C41 -> 10426 | D24: =C24/'都道府県_確率計算'!$C$57 -> 0.0155321 | E24: =SUM($D$9:D24) -> 0.71364981 | F24: ="["&CHAR(34)&B24&CHAR(34)&", "&TEXT(D24,"0.000000000000")&", "&TEXT(E24,"0.000000000000")&"]," -> ["岡山県", 0.015532100320, 0.713649805216], | G24: 41 | H24: 公式原表照合済み
A25: 17 | B25: ='都道府県_確率計算'!B51 -> 熊本県 | C25: ='都道府県_確率計算'!C51 -> 10193 | D25: =C25/'都道府県_確率計算'!$C$57 -> 0.015184989 | E25: =SUM($D$9:D25) -> 0.72883479 | F25: ="["&CHAR(34)&B25&CHAR(34)&", "&TEXT(D25,"0.000000000000")&", "&TEXT(E25,"0.000000000000")&"]," -> ["熊本県", 0.015184989311, 0.728834794527], | G25: 51 | H25: 公式原表照合済み
A26: 18 | B26: ='都道府県_確率計算'!B28 -> 長野県 | C26: ='都道府県_確率計算'!C28 -> 9875 | D26: =C26/'都道府県_確率計算'!$C$57 -> 0.01471125 | E26: =SUM($D$9:D26) -> 0.74354604 | F26: ="["&CHAR(34)&B26&CHAR(34)&", "&TEXT(D26,"0.000000000000")&", "&TEXT(E26,"0.000000000000")&"]," -> ["長野県", 0.014711249823, 0.743546044350], | G26: 28 | H26: 公式原表照合済み
A27: 19 | B27: ='都道府県_確率計算'!B23 -> 新潟県 | C27: ='都道府県_確率計算'!C23 -> 9580 | D27: =C27/'都道府県_確率計算'!$C$57 -> 0.014271775 | E27: =SUM($D$9:D27) -> 0.75781782 | F27: ="["&CHAR(34)&B27&CHAR(34)&", "&TEXT(D27,"0.000000000000")&", "&TEXT(E27,"0.000000000000")&"]," -> ["新潟県", 0.014271774512, 0.757817818862], | G27: 23 | H27: 公式原表照合済み
A28: 20 | B28: ='都道府県_確率計算'!B29 -> 岐阜県 | C28: ='都道府県_確率計算'!C29 -> 9351 | D28: =C28/'都道府県_確率計算'!$C$57 -> 0.013930622 | E28: =SUM($D$9:D28) -> 0.77174844 | F28: ="["&CHAR(34)&B28&CHAR(34)&", "&TEXT(D28,"0.000000000000")&", "&TEXT(E28,"0.000000000000")&"]," -> ["岐阜県", 0.013930622491, 0.771748441352], | G28: 29 | H28: 公式原表照合済み
A29: 21 | B29: ='都道府県_確率計算'!B18 -> 群馬県 | C29: ='都道府県_確率計算'!C18 -> 8950 | D29: =C29/'都道府県_確率計算'!$C$57 -> 0.013333234 | E29: =SUM($D$9:D29) -> 0.78508168 | F29: ="["&CHAR(34)&B29&CHAR(34)&", "&TEXT(D29,"0.000000000000")&", "&TEXT(E29,"0.000000000000")&"]," -> ["群馬県", 0.013333234017, 0.785081675369], | G29: 18 | H29: 公式原表照合済み
A30: 22 | B30: ='都道府県_確率計算'!B17 -> 栃木県 | C30: ='都道府県_確率計算'!C17 -> 8932 | D30: =C30/'都道府県_確率計算'!$C$57 -> 0.013306419 | E30: =SUM($D$9:D30) -> 0.79838809 | F30: ="["&CHAR(34)&B30&CHAR(34)&", "&TEXT(D30,"0.000000000000")&", "&TEXT(E30,"0.000000000000")&"]," -> ["栃木県", 0.013306418574, 0.798388093943], | G30: 17 | H30: 公式原表照合済み
A31: 23 | B31: ='都道府県_確率計算'!B32 -> 三重県 | C31: ='都道府県_確率計算'!C32 -> 8792 | D31: =C31/'都道府県_確率計算'!$C$57 -> 0.013097854 | E31: =SUM($D$9:D31) -> 0.81148595 | F31: ="["&CHAR(34)&B31&CHAR(34)&", "&TEXT(D31,"0.000000000000")&", "&TEXT(E31,"0.000000000000")&"]," -> ["三重県", 0.013097854020, 0.811485947963], | G31: 32 | H31: 公式原表照合済み
A32: 24 | B32: ='都道府県_確率計算'!B33 -> 滋賀県 | C32: ='都道府県_確率計算'!C33 -> 8708 | D32: =C32/'都道府県_確率計算'!$C$57 -> 0.012972715 | E32: =SUM($D$9:D32) -> 0.82445866 | F32: ="["&CHAR(34)&B32&CHAR(34)&", "&TEXT(D32,"0.000000000000")&", "&TEXT(E32,"0.000000000000")&"]," -> ["滋賀県", 0.012972715287, 0.824458663250], | G32: 33 | H32: 公式原表照合済み
A33: 25 | B33: ='都道府県_確率計算'!B54 -> 鹿児島県 | C33: ='都道府県_確率計算'!C54 -> 8661 | D33: =C33/'都道府県_確率計算'!$C$57 -> 0.012902697 | E33: =SUM($D$9:D33) -> 0.83736136 | F33: ="["&CHAR(34)&B33&CHAR(34)&", "&TEXT(D33,"0.000000000000")&", "&TEXT(E33,"0.000000000000")&"]," -> ["鹿児島県", 0.012902697187, 0.837361360437], | G33: 54 | H33: 公式原表照合済み
A34: 26 | B34: ='都道府県_確率計算'!B15 -> 福島県 | C34: ='都道府県_確率計算'!C15 -> 7842 | D34: =C34/'都道府県_確率計算'!$C$57 -> 0.011682595 | E34: =SUM($D$9:D34) -> 0.84904395 | F34: ="["&CHAR(34)&B34&CHAR(34)&", "&TEXT(D34,"0.000000000000")&", "&TEXT(E34,"0.000000000000")&"]," -> ["福島県", 0.011682594543, 0.849043954980], | G34: 15 | H34: 公式原表照合済み
A35: 27 | B35: ='都道府県_確率計算'!B50 -> 長崎県 | C35: ='都道府県_確率計算'!C50 -> 6846 | D35: =C35/'都道府県_確率計算'!$C$57 -> 0.010198807 | E35: =SUM($D$9:D35) -> 0.85924276 | F35: ="["&CHAR(34)&B35&CHAR(34)&", "&TEXT(D35,"0.000000000000")&", "&TEXT(E35,"0.000000000000")&"]," -> ["長崎県", 0.010198806713, 0.859242761693], | G35: 50 | H35: 公式原表照合済み
A36: 28 | B36: ='都道府県_確率計算'!B46 -> 愛媛県 | C36: ='都道府県_確率計算'!C46 -> 6422 | D36: =C36/'都道府県_確率計算'!$C$57 -> 0.0095671541 | E36: =SUM($D$9:D36) -> 0.86880992 | F36: ="["&CHAR(34)&B36&CHAR(34)&", "&TEXT(D36,"0.000000000000")&", "&TEXT(E36,"0.000000000000")&"]," -> ["愛媛県", 0.009567154062, 0.868809915755], | G36: 46 | H36: 公式原表照合済み
A37: 29 | B37: ='都道府県_確率計算'!B37 -> 奈良県 | C37: ='都道府県_確率計算'!C37 -> 6409 | D37: =C37/'都道府県_確率計算'!$C$57 -> 0.0095477874 | E37: =SUM($D$9:D37) -> 0.8783577 | F37: ="["&CHAR(34)&B37&CHAR(34)&", "&TEXT(D37,"0.000000000000")&", "&TEXT(E37,"0.000000000000")&"]," -> ["奈良県", 0.009547787354, 0.878357703108], | G37: 37 | H37: 公式原表照合済み
A38: 30 | B38: ='都道府県_確率計算'!B43 -> 山口県 | C38: ='都道府県_確率計算'!C43 -> 6401 | D38: =C38/'都道府県_確率計算'!$C$57 -> 0.0095358694 | E38: =SUM($D$9:D38) -> 0.88789357 | F38: ="["&CHAR(34)&B38&CHAR(34)&", "&TEXT(D38,"0.000000000000")&", "&TEXT(E38,"0.000000000000")&"]," -> ["山口県", 0.009535869379, 0.887893572487], | G38: 43 | H38: 公式原表照合済み
A39: 31 | B39: ='都道府県_確率計算'!B25 -> 石川県 | C39: ='都道府県_確率計算'!C25 -> 6242 | D39: =C39/'都道府県_確率計算'!$C$57 -> 0.0092989996 | E39: =SUM($D$9:D39) -> 0.89719257 | F39: ="["&CHAR(34)&B39&CHAR(34)&", "&TEXT(D39,"0.000000000000")&", "&TEXT(E39,"0.000000000000")&"]," -> ["石川県", 0.009298999635, 0.897192572122], | G39: 25 | H39: 公式原表照合済み
A40: 32 | B40: ='都道府県_確率計算'!B53 -> 宮崎県 | C40: ='都道府県_確率計算'!C53 -> 5923 | D40: =C40/'都道府県_確率計算'!$C$57 -> 0.0088237704 | E40: =SUM($D$9:D40) -> 0.90601634 | F40: ="["&CHAR(34)&B40&CHAR(34)&", "&TEXT(D40,"0.000000000000")&", "&TEXT(E40,"0.000000000000")&"]," -> ["宮崎県", 0.008823770400, 0.906016342523], | G40: 53 | H40: 公式原表照合済み
A41: 33 | B41: ='都道府県_確率計算'!B52 -> 大分県 | C41: ='都道府県_確率計算'!C52 -> 5666 | D41: =C41/'都道府県_確率計算'!$C$57 -> 0.0084409055 | E41: =SUM($D$9:D41) -> 0.91445725 | F41: ="["&CHAR(34)&B41&CHAR(34)&", "&TEXT(D41,"0.000000000000")&", "&TEXT(E41,"0.000000000000")&"]," -> ["大分県", 0.008440905468, 0.914457247991], | G41: 52 | H41: 公式原表照合済み
A42: 34 | B42: ='都道府県_確率計算'!B24 -> 富山県 | C42: ='都道府県_確率計算'!C24 -> 5125 | D42: =C42/'都道府県_確率計算'!$C$57 -> 0.0076349524 | E42: =SUM($D$9:D42) -> 0.9220922 | F42: ="["&CHAR(34)&B42&CHAR(34)&", "&TEXT(D42,"0.000000000000")&", "&TEXT(E42,"0.000000000000")&"]," -> ["富山県", 0.007634952440, 0.922092200431], | G42: 24 | H42: 公式原表照合済み
...
